[2024-10-10T06:59:41.581+0000] {local_task_job_runner.py:120} INFO - ::group::Pre task execution logs
[2024-10-10T06:59:41.874+0000] {taskinstance.py:2076} INFO - Dependencies all met for dep_context=non-requeueable deps ti=<TaskInstance: import_excel_to_oracle_dag.import_kpi_template scheduled__2024-10-08T10:00:00+00:00 [queued]>
[2024-10-10T06:59:41.892+0000] {taskinstance.py:2076} INFO - Dependencies all met for dep_context=requeueable deps ti=<TaskInstance: import_excel_to_oracle_dag.import_kpi_template scheduled__2024-10-08T10:00:00+00:00 [queued]>
[2024-10-10T06:59:41.895+0000] {taskinstance.py:2306} INFO - Starting attempt 1 of 2
[2024-10-10T06:59:41.929+0000] {taskinstance.py:2330} INFO - Executing <Task(PythonOperator): import_kpi_template> on 2024-10-08 10:00:00+00:00
[2024-10-10T06:59:41.950+0000] {logging_mixin.py:188} WARNING - /home/***/.local/lib/python3.12/site-packages/***/task/task_runner/standard_task_runner.py:62 DeprecationWarning: This process (pid=331) is multi-threaded, use of fork() may lead to deadlocks in the child.
[2024-10-10T06:59:41.947+0000] {standard_task_runner.py:90} INFO - Running: ['***', 'tasks', 'run', 'import_excel_to_oracle_dag', 'import_kpi_template', 'scheduled__2024-10-08T10:00:00+00:00', '--job-id', '10', '--raw', '--subdir', 'DAGS_FOLDER/oracle_dag.py', '--cfg-path', '/tmp/tmpvaf8orlw']
[2024-10-10T06:59:41.953+0000] {standard_task_runner.py:64} INFO - Started process 334 to run task
[2024-10-10T06:59:41.955+0000] {standard_task_runner.py:91} INFO - Job 10: Subtask import_kpi_template
[2024-10-10T06:59:41.988+0000] {logging_mixin.py:188} WARNING - /home/***/.local/lib/python3.12/site-packages/***/settings.py:195 DeprecationWarning: The sql_alchemy_conn option in [core] has been moved to the sql_alchemy_conn option in [database] - the old setting has been used, but please update your config.
[2024-10-10T06:59:42.081+0000] {task_command.py:426} INFO - Running <TaskInstance: import_excel_to_oracle_dag.import_kpi_template scheduled__2024-10-08T10:00:00+00:00 [running]> on host ec5690b705ef
[2024-10-10T06:59:42.305+0000] {taskinstance.py:2648} INFO - Exporting env vars: AIRFLOW_CTX_DAG_EMAIL='admin' AIRFLOW_CTX_DAG_OWNER='***' AIRFLOW_CTX_DAG_ID='import_excel_to_oracle_dag' AIRFLOW_CTX_TASK_ID='import_kpi_template' AIRFLOW_CTX_EXECUTION_DATE='2024-10-08T10:00:00+00:00' AIRFLOW_CTX_TRY_NUMBER='1' AIRFLOW_CTX_DAG_RUN_ID='scheduled__2024-10-08T10:00:00+00:00'
[2024-10-10T06:59:42.307+0000] {taskinstance.py:430} INFO - ::endgroup::
[2024-10-10T06:59:42.350+0000] {taskinstance.py:441} INFO - ::group::Post task execution logs
[2024-10-10T06:59:42.351+0000] {taskinstance.py:2905} ERROR - Task failed with exception
Traceback (most recent call last):
  File "/home/airflow/.local/lib/python3.12/site-packages/pandas/compat/_optional.py", line 132, in import_optional_dependency
    module = importlib.import_module(name)
             ^^^^^^^^^^^^^^^^^^^^^^^^^^^^^
  File "/usr/local/lib/python3.12/importlib/__init__.py", line 90, in import_module
    return _bootstrap._gcd_import(name[level:], package, level)
           ^^^^^^^^^^^^^^^^^^^^^^^^^^^^^^^^^^^^^^^^^^^^^^^^^^^^
  File "<frozen importlib._bootstrap>", line 1387, in _gcd_import
  File "<frozen importlib._bootstrap>", line 1360, in _find_and_load
  File "<frozen importlib._bootstrap>", line 1324, in _find_and_load_unlocked
ModuleNotFoundError: No module named 'openpyxl'

During handling of the above exception, another exception occurred:

Traceback (most recent call last):
  File "/home/airflow/.local/lib/python3.12/site-packages/airflow/models/taskinstance.py", line 465, in _execute_task
    result = _execute_callable(context=context, **execute_callable_kwargs)
             ^^^^^^^^^^^^^^^^^^^^^^^^^^^^^^^^^^^^^^^^^^^^^^^^^^^^^^^^^^^^^
  File "/home/airflow/.local/lib/python3.12/site-packages/airflow/models/taskinstance.py", line 432, in _execute_callable
    return execute_callable(context=context, **execute_callable_kwargs)
           ^^^^^^^^^^^^^^^^^^^^^^^^^^^^^^^^^^^^^^^^^^^^^^^^^^^^^^^^^^^^
  File "/home/airflow/.local/lib/python3.12/site-packages/airflow/models/baseoperator.py", line 401, in wrapper
    return func(self, *args, **kwargs)
           ^^^^^^^^^^^^^^^^^^^^^^^^^^^
  File "/home/airflow/.local/lib/python3.12/site-packages/airflow/operators/python.py", line 235, in execute
    return_value = self.execute_callable()
                   ^^^^^^^^^^^^^^^^^^^^^^^
  File "/home/airflow/.local/lib/python3.12/site-packages/airflow/operators/python.py", line 252, in execute_callable
    return self.python_callable(*self.op_args, **self.op_kwargs)
           ^^^^^^^^^^^^^^^^^^^^^^^^^^^^^^^^^^^^^^^^^^^^^^^^^^^^^
  File "/opt/airflow/dags/oracle_dag.py", line 66, in load_data_to_oracle
    df = pd.read_excel(file_path)
         ^^^^^^^^^^^^^^^^^^^^^^^^
  File "/home/airflow/.local/lib/python3.12/site-packages/pandas/io/excel/_base.py", line 504, in read_excel
    io = ExcelFile(
         ^^^^^^^^^^
  File "/home/airflow/.local/lib/python3.12/site-packages/pandas/io/excel/_base.py", line 1580, in __init__
    self._reader = self._engines[engine](
                   ^^^^^^^^^^^^^^^^^^^^^^
  File "/home/airflow/.local/lib/python3.12/site-packages/pandas/io/excel/_openpyxl.py", line 552, in __init__
    import_optional_dependency("openpyxl")
  File "/home/airflow/.local/lib/python3.12/site-packages/pandas/compat/_optional.py", line 135, in import_optional_dependency
    raise ImportError(msg)
ImportError: Missing optional dependency 'openpyxl'.  Use pip or conda to install openpyxl.
[2024-10-10T06:59:42.381+0000] {taskinstance.py:1206} INFO - Marking task as UP_FOR_RETRY. dag_id=import_excel_to_oracle_dag, task_id=import_kpi_template, run_id=scheduled__2024-10-08T10:00:00+00:00, execution_date=20241008T100000, start_date=20241010T065941, end_date=20241010T065942
[2024-10-10T06:59:42.413+0000] {logging_mixin.py:188} WARNING - /home/***/.local/lib/python3.12/site-packages/***/utils/email.py:154 RemovedInAirflow3Warning: Fetching SMTP credentials from configuration variables will be deprecated in a future release. Please set credentials using a connection instead.
[2024-10-10T06:59:42.414+0000] {configuration.py:1053} WARNING - section/key [smtp/smtp_user] not found in config
[2024-10-10T06:59:42.416+0000] {email.py:271} INFO - Email alerting: attempt 1
[2024-10-10T06:59:42.434+0000] {configuration.py:1053} WARNING - section/key [smtp/smtp_user] not found in config
[2024-10-10T06:59:42.435+0000] {email.py:271} INFO - Email alerting: attempt 1
[2024-10-10T06:59:42.437+0000] {taskinstance.py:879} ERROR - Failed to send email to: admin
Traceback (most recent call last):
  File "/home/airflow/.local/lib/python3.12/site-packages/pandas/compat/_optional.py", line 132, in import_optional_dependency
    module = importlib.import_module(name)
             ^^^^^^^^^^^^^^^^^^^^^^^^^^^^^
  File "/usr/local/lib/python3.12/importlib/__init__.py", line 90, in import_module
    return _bootstrap._gcd_import(name[level:], package, level)
           ^^^^^^^^^^^^^^^^^^^^^^^^^^^^^^^^^^^^^^^^^^^^^^^^^^^^
  File "<frozen importlib._bootstrap>", line 1387, in _gcd_import
  File "<frozen importlib._bootstrap>", line 1360, in _find_and_load
  File "<frozen importlib._bootstrap>", line 1324, in _find_and_load_unlocked
ModuleNotFoundError: No module named 'openpyxl'

During handling of the above exception, another exception occurred:

Traceback (most recent call last):
  File "/home/airflow/.local/lib/python3.12/site-packages/airflow/models/taskinstance.py", line 2479, in _run_raw_task
    self._execute_task_with_callbacks(context, test_mode, session=session)
  File "/home/airflow/.local/lib/python3.12/site-packages/airflow/models/taskinstance.py", line 2676, in _execute_task_with_callbacks
    result = self._execute_task(context, task_orig)
             ^^^^^^^^^^^^^^^^^^^^^^^^^^^^^^^^^^^^^^
  File "/home/airflow/.local/lib/python3.12/site-packages/airflow/models/taskinstance.py", line 2701, in _execute_task
    return _execute_task(self, context, task_orig)
           ^^^^^^^^^^^^^^^^^^^^^^^^^^^^^^^^^^^^^^^
  File "/home/airflow/.local/lib/python3.12/site-packages/airflow/models/taskinstance.py", line 465, in _execute_task
    result = _execute_callable(context=context, **execute_callable_kwargs)
             ^^^^^^^^^^^^^^^^^^^^^^^^^^^^^^^^^^^^^^^^^^^^^^^^^^^^^^^^^^^^^
  File "/home/airflow/.local/lib/python3.12/site-packages/airflow/models/taskinstance.py", line 432, in _execute_callable
    return execute_callable(context=context, **execute_callable_kwargs)
           ^^^^^^^^^^^^^^^^^^^^^^^^^^^^^^^^^^^^^^^^^^^^^^^^^^^^^^^^^^^^
  File "/home/airflow/.local/lib/python3.12/site-packages/airflow/models/baseoperator.py", line 401, in wrapper
    return func(self, *args, **kwargs)
           ^^^^^^^^^^^^^^^^^^^^^^^^^^^
  File "/home/airflow/.local/lib/python3.12/site-packages/airflow/operators/python.py", line 235, in execute
    return_value = self.execute_callable()
                   ^^^^^^^^^^^^^^^^^^^^^^^
  File "/home/airflow/.local/lib/python3.12/site-packages/airflow/operators/python.py", line 252, in execute_callable
    return self.python_callable(*self.op_args, **self.op_kwargs)
           ^^^^^^^^^^^^^^^^^^^^^^^^^^^^^^^^^^^^^^^^^^^^^^^^^^^^^
  File "/opt/airflow/dags/oracle_dag.py", line 66, in load_data_to_oracle
    df = pd.read_excel(file_path)
         ^^^^^^^^^^^^^^^^^^^^^^^^
  File "/home/airflow/.local/lib/python3.12/site-packages/pandas/io/excel/_base.py", line 504, in read_excel
    io = ExcelFile(
         ^^^^^^^^^^
  File "/home/airflow/.local/lib/python3.12/site-packages/pandas/io/excel/_base.py", line 1580, in __init__
    self._reader = self._engines[engine](
                   ^^^^^^^^^^^^^^^^^^^^^^
  File "/home/airflow/.local/lib/python3.12/site-packages/pandas/io/excel/_openpyxl.py", line 552, in __init__
    import_optional_dependency("openpyxl")
  File "/home/airflow/.local/lib/python3.12/site-packages/pandas/compat/_optional.py", line 135, in import_optional_dependency
    raise ImportError(msg)
ImportError: Missing optional dependency 'openpyxl'.  Use pip or conda to install openpyxl.

During handling of the above exception, another exception occurred:

Traceback (most recent call last):
  File "/home/airflow/.local/lib/python3.12/site-packages/airflow/models/taskinstance.py", line 1063, in _email_alert
    send_email(task.email, subject, html_content)
  File "/home/airflow/.local/lib/python3.12/site-packages/airflow/utils/email.py", line 80, in send_email
    return backend(
           ^^^^^^^^
  File "/home/airflow/.local/lib/python3.12/site-packages/airflow/utils/email.py", line 154, in send_email_smtp
    send_mime_email(e_from=mail_from, e_to=recipients, mime_msg=msg, conn_id=conn_id, dryrun=dryrun)
  File "/home/airflow/.local/lib/python3.12/site-packages/airflow/utils/email.py", line 273, in send_mime_email
    smtp_conn = _get_smtp_connection(smtp_host, smtp_port, smtp_timeout, smtp_ssl)
                ^^^^^^^^^^^^^^^^^^^^^^^^^^^^^^^^^^^^^^^^^^^^^^^^^^^^^^^^^^^^^^^^^^
  File "/home/airflow/.local/lib/python3.12/site-packages/airflow/utils/email.py", line 317, in _get_smtp_connection
    return smtplib.SMTP(host=host, port=port, timeout=timeout)
           ^^^^^^^^^^^^^^^^^^^^^^^^^^^^^^^^^^^^^^^^^^^^^^^^^^^
  File "/usr/local/lib/python3.12/smtplib.py", line 255, in __init__
    (code, msg) = self.connect(host, port)
                  ^^^^^^^^^^^^^^^^^^^^^^^^
  File "/usr/local/lib/python3.12/smtplib.py", line 341, in connect
    self.sock = self._get_socket(host, port, self.timeout)
                ^^^^^^^^^^^^^^^^^^^^^^^^^^^^^^^^^^^^^^^^^^
  File "/usr/local/lib/python3.12/smtplib.py", line 312, in _get_socket
    return socket.create_connection((host, port), timeout,
           ^^^^^^^^^^^^^^^^^^^^^^^^^^^^^^^^^^^^^^^^^^^^^^^
  File "/usr/local/lib/python3.12/socket.py", line 853, in create_connection
    raise exceptions[0]
  File "/usr/local/lib/python3.12/socket.py", line 838, in create_connection
    sock.connect(sa)
ConnectionRefusedError: [Errno 111] Connection refused

During handling of the above exception, another exception occurred:

Traceback (most recent call last):
  File "/home/airflow/.local/lib/python3.12/site-packages/airflow/models/taskinstance.py", line 877, in _handle_failure
    task_instance.email_alert(error, failure_context["task"])
  File "/home/airflow/.local/lib/python3.12/site-packages/airflow/models/taskinstance.py", line 3163, in email_alert
    _email_alert(task_instance=self, exception=exception, task=task)
  File "/home/airflow/.local/lib/python3.12/site-packages/airflow/models/taskinstance.py", line 1065, in _email_alert
    send_email(task.email, subject, html_content_err)
  File "/home/airflow/.local/lib/python3.12/site-packages/airflow/utils/email.py", line 80, in send_email
    return backend(
           ^^^^^^^^
  File "/home/airflow/.local/lib/python3.12/site-packages/airflow/utils/email.py", line 154, in send_email_smtp
    send_mime_email(e_from=mail_from, e_to=recipients, mime_msg=msg, conn_id=conn_id, dryrun=dryrun)
  File "/home/airflow/.local/lib/python3.12/site-packages/airflow/utils/email.py", line 273, in send_mime_email
    smtp_conn = _get_smtp_connection(smtp_host, smtp_port, smtp_timeout, smtp_ssl)
                ^^^^^^^^^^^^^^^^^^^^^^^^^^^^^^^^^^^^^^^^^^^^^^^^^^^^^^^^^^^^^^^^^^
  File "/home/airflow/.local/lib/python3.12/site-packages/airflow/utils/email.py", line 317, in _get_smtp_connection
    return smtplib.SMTP(host=host, port=port, timeout=timeout)
           ^^^^^^^^^^^^^^^^^^^^^^^^^^^^^^^^^^^^^^^^^^^^^^^^^^^
  File "/usr/local/lib/python3.12/smtplib.py", line 255, in __init__
    (code, msg) = self.connect(host, port)
                  ^^^^^^^^^^^^^^^^^^^^^^^^
  File "/usr/local/lib/python3.12/smtplib.py", line 341, in connect
    self.sock = self._get_socket(host, port, self.timeout)
                ^^^^^^^^^^^^^^^^^^^^^^^^^^^^^^^^^^^^^^^^^^
  File "/usr/local/lib/python3.12/smtplib.py", line 312, in _get_socket
    return socket.create_connection((host, port), timeout,
           ^^^^^^^^^^^^^^^^^^^^^^^^^^^^^^^^^^^^^^^^^^^^^^^
  File "/usr/local/lib/python3.12/socket.py", line 853, in create_connection
    raise exceptions[0]
  File "/usr/local/lib/python3.12/socket.py", line 838, in create_connection
    sock.connect(sa)
ConnectionRefusedError: [Errno 111] Connection refused
[2024-10-10T06:59:42.479+0000] {standard_task_runner.py:110} ERROR - Failed to execute job 10 for task import_kpi_template (Missing optional dependency 'openpyxl'.  Use pip or conda to install openpyxl.; 334)
[2024-10-10T06:59:42.495+0000] {local_task_job_runner.py:243} INFO - Task exited with return code 1
[2024-10-10T06:59:42.546+0000] {taskinstance.py:3503} INFO - 0 downstream tasks scheduled from follow-on schedule check
[2024-10-10T06:59:42.556+0000] {local_task_job_runner.py:222} INFO - ::endgroup::
[2024-10-10T07:34:45.004+0000] {local_task_job_runner.py:120} INFO - ::group::Pre task execution logs
[2024-10-10T07:34:45.646+0000] {taskinstance.py:2076} INFO - Dependencies all met for dep_context=non-requeueable deps ti=<TaskInstance: import_excel_to_oracle_dag.import_kpi_template scheduled__2024-10-08T10:00:00+00:00 [queued]>
[2024-10-10T07:34:45.671+0000] {taskinstance.py:2076} INFO - Dependencies all met for dep_context=requeueable deps ti=<TaskInstance: import_excel_to_oracle_dag.import_kpi_template scheduled__2024-10-08T10:00:00+00:00 [queued]>
[2024-10-10T07:34:45.672+0000] {taskinstance.py:2306} INFO - Starting attempt 1 of 2
[2024-10-10T07:34:45.718+0000] {taskinstance.py:2330} INFO - Executing <Task(PythonOperator): import_kpi_template> on 2024-10-08 10:00:00+00:00
[2024-10-10T07:34:45.741+0000] {logging_mixin.py:188} WARNING - /home/***/.local/lib/python3.12/site-packages/***/task/task_runner/standard_task_runner.py:62 DeprecationWarning: This process (pid=267) is multi-threaded, use of fork() may lead to deadlocks in the child.
[2024-10-10T07:34:45.740+0000] {standard_task_runner.py:90} INFO - Running: ['***', 'tasks', 'run', 'import_excel_to_oracle_dag', 'import_kpi_template', 'scheduled__2024-10-08T10:00:00+00:00', '--job-id', '22', '--raw', '--subdir', 'DAGS_FOLDER/oracle_dag.py', '--cfg-path', '/tmp/tmpbcctl0l8']
[2024-10-10T07:34:45.746+0000] {standard_task_runner.py:64} INFO - Started process 270 to run task
[2024-10-10T07:34:45.747+0000] {standard_task_runner.py:91} INFO - Job 22: Subtask import_kpi_template
[2024-10-10T07:34:45.787+0000] {logging_mixin.py:188} WARNING - /home/***/.local/lib/python3.12/site-packages/***/settings.py:195 DeprecationWarning: The sql_alchemy_conn option in [core] has been moved to the sql_alchemy_conn option in [database] - the old setting has been used, but please update your config.
[2024-10-10T07:34:45.901+0000] {task_command.py:426} INFO - Running <TaskInstance: import_excel_to_oracle_dag.import_kpi_template scheduled__2024-10-08T10:00:00+00:00 [running]> on host 751c06a3cc64
[2024-10-10T07:34:46.128+0000] {taskinstance.py:2648} INFO - Exporting env vars: AIRFLOW_CTX_DAG_EMAIL='admin' AIRFLOW_CTX_DAG_OWNER='***' AIRFLOW_CTX_DAG_ID='import_excel_to_oracle_dag' AIRFLOW_CTX_TASK_ID='import_kpi_template' AIRFLOW_CTX_EXECUTION_DATE='2024-10-08T10:00:00+00:00' AIRFLOW_CTX_TRY_NUMBER='1' AIRFLOW_CTX_DAG_RUN_ID='scheduled__2024-10-08T10:00:00+00:00'
[2024-10-10T07:34:46.131+0000] {taskinstance.py:430} INFO - ::endgroup::
[2024-10-10T07:34:46.521+0000] {base.py:84} INFO - Using connection ID 'oracle_conn_id' for task execution.
[2024-10-10T07:34:46.531+0000] {taskinstance.py:441} INFO - ::group::Post task execution logs
[2024-10-10T07:34:46.533+0000] {taskinstance.py:2905} ERROR - Task failed with exception
Traceback (most recent call last):
  File "src/oracledb/impl/thin/connection.pyx", line 322, in oracledb.thin_impl.ThinConnImpl._connect_with_address
  File "src/oracledb/impl/thin/protocol.pyx", line 225, in oracledb.thin_impl.Protocol._connect_phase_one
  File "src/oracledb/impl/thin/protocol.pyx", line 362, in oracledb.thin_impl.Protocol._connect_tcp
  File "/usr/local/lib/python3.12/socket.py", line 829, in create_connection
    for res in getaddrinfo(host, port, 0, SOCK_STREAM):
               ^^^^^^^^^^^^^^^^^^^^^^^^^^^^^^^^^^^^^^^
  File "/usr/local/lib/python3.12/socket.py", line 964, in getaddrinfo
    for res in _socket.getaddrinfo(host, port, family, type, proto, flags):
               ^^^^^^^^^^^^^^^^^^^^^^^^^^^^^^^^^^^^^^^^^^^^^^^^^^^^^^^^^^^
socket.gaierror: [Errno -5] No address associated with hostname

The above exception was the direct cause of the following exception:

Traceback (most recent call last):
  File "/home/airflow/.local/lib/python3.12/site-packages/airflow/models/taskinstance.py", line 465, in _execute_task
    result = _execute_callable(context=context, **execute_callable_kwargs)
             ^^^^^^^^^^^^^^^^^^^^^^^^^^^^^^^^^^^^^^^^^^^^^^^^^^^^^^^^^^^^^
  File "/home/airflow/.local/lib/python3.12/site-packages/airflow/models/taskinstance.py", line 432, in _execute_callable
    return execute_callable(context=context, **execute_callable_kwargs)
           ^^^^^^^^^^^^^^^^^^^^^^^^^^^^^^^^^^^^^^^^^^^^^^^^^^^^^^^^^^^^
  File "/home/airflow/.local/lib/python3.12/site-packages/airflow/models/baseoperator.py", line 401, in wrapper
    return func(self, *args, **kwargs)
           ^^^^^^^^^^^^^^^^^^^^^^^^^^^
  File "/home/airflow/.local/lib/python3.12/site-packages/airflow/operators/python.py", line 235, in execute
    return_value = self.execute_callable()
                   ^^^^^^^^^^^^^^^^^^^^^^^
  File "/home/airflow/.local/lib/python3.12/site-packages/airflow/operators/python.py", line 252, in execute_callable
    return self.python_callable(*self.op_args, **self.op_kwargs)
           ^^^^^^^^^^^^^^^^^^^^^^^^^^^^^^^^^^^^^^^^^^^^^^^^^^^^^
  File "/opt/airflow/dags/oracle_dag.py", line 70, in load_data_to_oracle
    connection = oracle_hook.get_conn()
                 ^^^^^^^^^^^^^^^^^^^^^^
  File "/home/airflow/.local/lib/python3.12/site-packages/airflow/providers/oracle/hooks/oracle.py", line 237, in get_conn
    conn = oracledb.connect(**conn_config)
           ^^^^^^^^^^^^^^^^^^^^^^^^^^^^^^^
  File "/home/airflow/.local/lib/python3.12/site-packages/oracledb/connection.py", line 1169, in connect
    return conn_class(dsn=dsn, pool=pool, params=params, **kwargs)
           ^^^^^^^^^^^^^^^^^^^^^^^^^^^^^^^^^^^^^^^^^^^^^^^^^^^^^^^
  File "/home/airflow/.local/lib/python3.12/site-packages/oracledb/connection.py", line 551, in __init__
    impl.connect(params_impl)
  File "src/oracledb/impl/thin/connection.pyx", line 424, in oracledb.thin_impl.ThinConnImpl.connect
  File "src/oracledb/impl/thin/connection.pyx", line 420, in oracledb.thin_impl.ThinConnImpl.connect
  File "src/oracledb/impl/thin/connection.pyx", line 380, in oracledb.thin_impl.ThinConnImpl._connect_with_params
  File "src/oracledb/impl/thin/connection.pyx", line 361, in oracledb.thin_impl.ThinConnImpl._connect_with_description
  File "src/oracledb/impl/thin/connection.pyx", line 327, in oracledb.thin_impl.ThinConnImpl._connect_with_address
  File "/home/airflow/.local/lib/python3.12/site-packages/oracledb/errors.py", line 195, in _raise_err
    raise error.exc_type(error) from cause
oracledb.exceptions.OperationalError: DPY-6005: cannot connect to database (CONNECTION_ID=PnS+oRmsJ4sqy4037S2hyg==).
[Errno -5] No address associated with hostname
[2024-10-10T07:34:46.566+0000] {taskinstance.py:1206} INFO - Marking task as UP_FOR_RETRY. dag_id=import_excel_to_oracle_dag, task_id=import_kpi_template, run_id=scheduled__2024-10-08T10:00:00+00:00, execution_date=20241008T100000, start_date=20241010T073445, end_date=20241010T073446
[2024-10-10T07:34:46.599+0000] {logging_mixin.py:188} WARNING - /home/***/.local/lib/python3.12/site-packages/***/utils/email.py:154 RemovedInAirflow3Warning: Fetching SMTP credentials from configuration variables will be deprecated in a future release. Please set credentials using a connection instead.
[2024-10-10T07:34:46.601+0000] {configuration.py:1053} WARNING - section/key [smtp/smtp_user] not found in config
[2024-10-10T07:34:46.602+0000] {email.py:271} INFO - Email alerting: attempt 1
[2024-10-10T07:34:46.618+0000] {configuration.py:1053} WARNING - section/key [smtp/smtp_user] not found in config
[2024-10-10T07:34:46.619+0000] {email.py:271} INFO - Email alerting: attempt 1
[2024-10-10T07:34:46.621+0000] {taskinstance.py:879} ERROR - Failed to send email to: ***
Traceback (most recent call last):
  File "src/oracledb/impl/thin/connection.pyx", line 322, in oracledb.thin_impl.ThinConnImpl._connect_with_address
  File "src/oracledb/impl/thin/protocol.pyx", line 225, in oracledb.thin_impl.Protocol._connect_phase_one
  File "src/oracledb/impl/thin/protocol.pyx", line 362, in oracledb.thin_impl.Protocol._connect_tcp
  File "/usr/local/lib/python3.12/socket.py", line 829, in create_connection
    for res in getaddrinfo(host, port, 0, SOCK_STREAM):
               ^^^^^^^^^^^^^^^^^^^^^^^^^^^^^^^^^^^^^^^
  File "/usr/local/lib/python3.12/socket.py", line 964, in getaddrinfo
    for res in _socket.getaddrinfo(host, port, family, type, proto, flags):
               ^^^^^^^^^^^^^^^^^^^^^^^^^^^^^^^^^^^^^^^^^^^^^^^^^^^^^^^^^^^
socket.gaierror: [Errno -5] No address associated with hostname

The above exception was the direct cause of the following exception:

Traceback (most recent call last):
  File "/home/airflow/.local/lib/python3.12/site-packages/airflow/models/taskinstance.py", line 2479, in _run_raw_task
    self._execute_task_with_callbacks(context, test_mode, session=session)
  File "/home/airflow/.local/lib/python3.12/site-packages/airflow/models/taskinstance.py", line 2676, in _execute_task_with_callbacks
    result = self._execute_task(context, task_orig)
             ^^^^^^^^^^^^^^^^^^^^^^^^^^^^^^^^^^^^^^
  File "/home/airflow/.local/lib/python3.12/site-packages/airflow/models/taskinstance.py", line 2701, in _execute_task
    return _execute_task(self, context, task_orig)
           ^^^^^^^^^^^^^^^^^^^^^^^^^^^^^^^^^^^^^^^
  File "/home/airflow/.local/lib/python3.12/site-packages/airflow/models/taskinstance.py", line 465, in _execute_task
    result = _execute_callable(context=context, **execute_callable_kwargs)
             ^^^^^^^^^^^^^^^^^^^^^^^^^^^^^^^^^^^^^^^^^^^^^^^^^^^^^^^^^^^^^
  File "/home/airflow/.local/lib/python3.12/site-packages/airflow/models/taskinstance.py", line 432, in _execute_callable
    return execute_callable(context=context, **execute_callable_kwargs)
           ^^^^^^^^^^^^^^^^^^^^^^^^^^^^^^^^^^^^^^^^^^^^^^^^^^^^^^^^^^^^
  File "/home/airflow/.local/lib/python3.12/site-packages/airflow/models/baseoperator.py", line 401, in wrapper
    return func(self, *args, **kwargs)
           ^^^^^^^^^^^^^^^^^^^^^^^^^^^
  File "/home/airflow/.local/lib/python3.12/site-packages/airflow/operators/python.py", line 235, in execute
    return_value = self.execute_callable()
                   ^^^^^^^^^^^^^^^^^^^^^^^
  File "/home/airflow/.local/lib/python3.12/site-packages/airflow/operators/python.py", line 252, in execute_callable
    return self.python_callable(*self.op_args, **self.op_kwargs)
           ^^^^^^^^^^^^^^^^^^^^^^^^^^^^^^^^^^^^^^^^^^^^^^^^^^^^^
  File "/opt/airflow/dags/oracle_dag.py", line 70, in load_data_to_oracle
    connection = oracle_hook.get_conn()
                 ^^^^^^^^^^^^^^^^^^^^^^
  File "/home/airflow/.local/lib/python3.12/site-packages/airflow/providers/oracle/hooks/oracle.py", line 237, in get_conn
    conn = oracledb.connect(**conn_config)
           ^^^^^^^^^^^^^^^^^^^^^^^^^^^^^^^
  File "/home/airflow/.local/lib/python3.12/site-packages/oracledb/connection.py", line 1169, in connect
    return conn_class(dsn=dsn, pool=pool, params=params, **kwargs)
           ^^^^^^^^^^^^^^^^^^^^^^^^^^^^^^^^^^^^^^^^^^^^^^^^^^^^^^^
  File "/home/airflow/.local/lib/python3.12/site-packages/oracledb/connection.py", line 551, in __init__
    impl.connect(params_impl)
  File "src/oracledb/impl/thin/connection.pyx", line 424, in oracledb.thin_impl.ThinConnImpl.connect
  File "src/oracledb/impl/thin/connection.pyx", line 420, in oracledb.thin_impl.ThinConnImpl.connect
  File "src/oracledb/impl/thin/connection.pyx", line 380, in oracledb.thin_impl.ThinConnImpl._connect_with_params
  File "src/oracledb/impl/thin/connection.pyx", line 361, in oracledb.thin_impl.ThinConnImpl._connect_with_description
  File "src/oracledb/impl/thin/connection.pyx", line 327, in oracledb.thin_impl.ThinConnImpl._connect_with_address
  File "/home/airflow/.local/lib/python3.12/site-packages/oracledb/errors.py", line 195, in _raise_err
    raise error.exc_type(error) from cause
oracledb.exceptions.OperationalError: DPY-6005: cannot connect to database (CONNECTION_ID=PnS+oRmsJ4sqy4037S2hyg==).
[Errno -5] No address associated with hostname

During handling of the above exception, another exception occurred:

Traceback (most recent call last):
  File "/home/airflow/.local/lib/python3.12/site-packages/airflow/models/taskinstance.py", line 1063, in _email_alert
    send_email(task.email, subject, html_content)
  File "/home/airflow/.local/lib/python3.12/site-packages/airflow/utils/email.py", line 80, in send_email
    return backend(
           ^^^^^^^^
  File "/home/airflow/.local/lib/python3.12/site-packages/airflow/utils/email.py", line 154, in send_email_smtp
    send_mime_email(e_from=mail_from, e_to=recipients, mime_msg=msg, conn_id=conn_id, dryrun=dryrun)
  File "/home/airflow/.local/lib/python3.12/site-packages/airflow/utils/email.py", line 273, in send_mime_email
    smtp_conn = _get_smtp_connection(smtp_host, smtp_port, smtp_timeout, smtp_ssl)
                ^^^^^^^^^^^^^^^^^^^^^^^^^^^^^^^^^^^^^^^^^^^^^^^^^^^^^^^^^^^^^^^^^^
  File "/home/airflow/.local/lib/python3.12/site-packages/airflow/utils/email.py", line 317, in _get_smtp_connection
    return smtplib.SMTP(host=host, port=port, timeout=timeout)
           ^^^^^^^^^^^^^^^^^^^^^^^^^^^^^^^^^^^^^^^^^^^^^^^^^^^
  File "/usr/local/lib/python3.12/smtplib.py", line 255, in __init__
    (code, msg) = self.connect(host, port)
                  ^^^^^^^^^^^^^^^^^^^^^^^^
  File "/usr/local/lib/python3.12/smtplib.py", line 341, in connect
    self.sock = self._get_socket(host, port, self.timeout)
                ^^^^^^^^^^^^^^^^^^^^^^^^^^^^^^^^^^^^^^^^^^
  File "/usr/local/lib/python3.12/smtplib.py", line 312, in _get_socket
    return socket.create_connection((host, port), timeout,
           ^^^^^^^^^^^^^^^^^^^^^^^^^^^^^^^^^^^^^^^^^^^^^^^
  File "/usr/local/lib/python3.12/socket.py", line 853, in create_connection
    raise exceptions[0]
  File "/usr/local/lib/python3.12/socket.py", line 838, in create_connection
    sock.connect(sa)
ConnectionRefusedError: [Errno 111] Connection refused

During handling of the above exception, another exception occurred:

Traceback (most recent call last):
  File "/home/airflow/.local/lib/python3.12/site-packages/airflow/models/taskinstance.py", line 877, in _handle_failure
    task_instance.email_alert(error, failure_context["task"])
  File "/home/airflow/.local/lib/python3.12/site-packages/airflow/models/taskinstance.py", line 3163, in email_alert
    _email_alert(task_instance=self, exception=exception, task=task)
  File "/home/airflow/.local/lib/python3.12/site-packages/airflow/models/taskinstance.py", line 1065, in _email_alert
    send_email(task.email, subject, html_content_err)
  File "/home/airflow/.local/lib/python3.12/site-packages/airflow/utils/email.py", line 80, in send_email
    return backend(
           ^^^^^^^^
  File "/home/airflow/.local/lib/python3.12/site-packages/airflow/utils/email.py", line 154, in send_email_smtp
    send_mime_email(e_from=mail_from, e_to=recipients, mime_msg=msg, conn_id=conn_id, dryrun=dryrun)
  File "/home/airflow/.local/lib/python3.12/site-packages/airflow/utils/email.py", line 273, in send_mime_email
    smtp_conn = _get_smtp_connection(smtp_host, smtp_port, smtp_timeout, smtp_ssl)
                ^^^^^^^^^^^^^^^^^^^^^^^^^^^^^^^^^^^^^^^^^^^^^^^^^^^^^^^^^^^^^^^^^^
  File "/home/airflow/.local/lib/python3.12/site-packages/airflow/utils/email.py", line 317, in _get_smtp_connection
    return smtplib.SMTP(host=host, port=port, timeout=timeout)
           ^^^^^^^^^^^^^^^^^^^^^^^^^^^^^^^^^^^^^^^^^^^^^^^^^^^
  File "/usr/local/lib/python3.12/smtplib.py", line 255, in __init__
    (code, msg) = self.connect(host, port)
                  ^^^^^^^^^^^^^^^^^^^^^^^^
  File "/usr/local/lib/python3.12/smtplib.py", line 341, in connect
    self.sock = self._get_socket(host, port, self.timeout)
                ^^^^^^^^^^^^^^^^^^^^^^^^^^^^^^^^^^^^^^^^^^
  File "/usr/local/lib/python3.12/smtplib.py", line 312, in _get_socket
    return socket.create_connection((host, port), timeout,
           ^^^^^^^^^^^^^^^^^^^^^^^^^^^^^^^^^^^^^^^^^^^^^^^
  File "/usr/local/lib/python3.12/socket.py", line 853, in create_connection
    raise exceptions[0]
  File "/usr/local/lib/python3.12/socket.py", line 838, in create_connection
    sock.connect(sa)
ConnectionRefusedError: [Errno 111] Connection refused
[2024-10-10T07:34:46.662+0000] {standard_task_runner.py:110} ERROR - Failed to execute job 22 for task import_kpi_template (DPY-6005: cannot connect to database (CONNECTION_ID=PnS+oRmsJ4sqy4037S2hyg==).
[Errno -5] No address associated with hostname; 270)
[2024-10-10T07:34:46.691+0000] {local_task_job_runner.py:243} INFO - Task exited with return code 1
[2024-10-10T07:34:46.739+0000] {taskinstance.py:3503} INFO - 0 downstream tasks scheduled from follow-on schedule check
[2024-10-10T07:34:46.746+0000] {local_task_job_runner.py:222} INFO - ::endgroup::
