[2024-10-10T07:35:33.567+0000] {local_task_job_runner.py:120} INFO - ::group::Pre task execution logs
[2024-10-10T07:35:34.293+0000] {taskinstance.py:2076} INFO - Dependencies all met for dep_context=non-requeueable deps ti=<TaskInstance: import_excel_to_oracle_dag.import_kpi_template manual__2024-10-10T07:35:30.741567+00:00 [queued]>
[2024-10-10T07:35:34.338+0000] {taskinstance.py:2076} INFO - Dependencies all met for dep_context=requeueable deps ti=<TaskInstance: import_excel_to_oracle_dag.import_kpi_template manual__2024-10-10T07:35:30.741567+00:00 [queued]>
[2024-10-10T07:35:34.344+0000] {taskinstance.py:2306} INFO - Starting attempt 1 of 2
[2024-10-10T07:35:34.428+0000] {taskinstance.py:2330} INFO - Executing <Task(PythonOperator): import_kpi_template> on 2024-10-10 07:35:30.741567+00:00
[2024-10-10T07:35:34.472+0000] {logging_mixin.py:188} WARNING - /home/***/.local/lib/python3.12/site-packages/***/task/task_runner/standard_task_runner.py:62 DeprecationWarning: This process (pid=306) is multi-threaded, use of fork() may lead to deadlocks in the child.
[2024-10-10T07:35:34.472+0000] {standard_task_runner.py:90} INFO - Running: ['***', 'tasks', 'run', 'import_excel_to_oracle_dag', 'import_kpi_template', 'manual__2024-10-10T07:35:30.741567+00:00', '--job-id', '23', '--raw', '--subdir', 'DAGS_FOLDER/oracle_dag.py', '--cfg-path', '/tmp/tmpj0ft0u46']
[2024-10-10T07:35:34.487+0000] {standard_task_runner.py:64} INFO - Started process 316 to run task
[2024-10-10T07:35:34.491+0000] {standard_task_runner.py:91} INFO - Job 23: Subtask import_kpi_template
[2024-10-10T07:35:34.561+0000] {logging_mixin.py:188} WARNING - /home/***/.local/lib/python3.12/site-packages/***/settings.py:195 DeprecationWarning: The sql_alchemy_conn option in [core] has been moved to the sql_alchemy_conn option in [database] - the old setting has been used, but please update your config.
[2024-10-10T07:35:34.649+0000] {task_command.py:426} INFO - Running <TaskInstance: import_excel_to_oracle_dag.import_kpi_template manual__2024-10-10T07:35:30.741567+00:00 [running]> on host 751c06a3cc64
[2024-10-10T07:35:34.946+0000] {taskinstance.py:2648} INFO - Exporting env vars: AIRFLOW_CTX_DAG_EMAIL='admin' AIRFLOW_CTX_DAG_OWNER='***' AIRFLOW_CTX_DAG_ID='import_excel_to_oracle_dag' AIRFLOW_CTX_TASK_ID='import_kpi_template' AIRFLOW_CTX_EXECUTION_DATE='2024-10-10T07:35:30.741567+00:00' AIRFLOW_CTX_TRY_NUMBER='1' AIRFLOW_CTX_DAG_RUN_ID='manual__2024-10-10T07:35:30.741567+00:00'
[2024-10-10T07:35:34.949+0000] {taskinstance.py:430} INFO - ::endgroup::
[2024-10-10T07:35:35.396+0000] {base.py:84} INFO - Using connection ID 'oracle_conn_id' for task execution.
[2024-10-10T07:35:35.408+0000] {taskinstance.py:441} INFO - ::group::Post task execution logs
[2024-10-10T07:35:35.410+0000] {taskinstance.py:2905} ERROR - Task failed with exception
Traceback (most recent call last):
  File "src/oracledb/impl/thin/connection.pyx", line 322, in oracledb.thin_impl.ThinConnImpl._connect_with_address
  File "src/oracledb/impl/thin/protocol.pyx", line 225, in oracledb.thin_impl.Protocol._connect_phase_one
  File "src/oracledb/impl/thin/protocol.pyx", line 362, in oracledb.thin_impl.Protocol._connect_tcp
  File "/usr/local/lib/python3.12/socket.py", line 829, in create_connection
    for res in getaddrinfo(host, port, 0, SOCK_STREAM):
               ^^^^^^^^^^^^^^^^^^^^^^^^^^^^^^^^^^^^^^^
  File "/usr/local/lib/python3.12/socket.py", line 964, in getaddrinfo
    for res in _socket.getaddrinfo(host, port, family, type, proto, flags):
               ^^^^^^^^^^^^^^^^^^^^^^^^^^^^^^^^^^^^^^^^^^^^^^^^^^^^^^^^^^^
socket.gaierror: [Errno -5] No address associated with hostname

The above exception was the direct cause of the following exception:

Traceback (most recent call last):
  File "/home/airflow/.local/lib/python3.12/site-packages/airflow/models/taskinstance.py", line 465, in _execute_task
    result = _execute_callable(context=context, **execute_callable_kwargs)
             ^^^^^^^^^^^^^^^^^^^^^^^^^^^^^^^^^^^^^^^^^^^^^^^^^^^^^^^^^^^^^
  File "/home/airflow/.local/lib/python3.12/site-packages/airflow/models/taskinstance.py", line 432, in _execute_callable
    return execute_callable(context=context, **execute_callable_kwargs)
           ^^^^^^^^^^^^^^^^^^^^^^^^^^^^^^^^^^^^^^^^^^^^^^^^^^^^^^^^^^^^
  File "/home/airflow/.local/lib/python3.12/site-packages/airflow/models/baseoperator.py", line 401, in wrapper
    return func(self, *args, **kwargs)
           ^^^^^^^^^^^^^^^^^^^^^^^^^^^
  File "/home/airflow/.local/lib/python3.12/site-packages/airflow/operators/python.py", line 235, in execute
    return_value = self.execute_callable()
                   ^^^^^^^^^^^^^^^^^^^^^^^
  File "/home/airflow/.local/lib/python3.12/site-packages/airflow/operators/python.py", line 252, in execute_callable
    return self.python_callable(*self.op_args, **self.op_kwargs)
           ^^^^^^^^^^^^^^^^^^^^^^^^^^^^^^^^^^^^^^^^^^^^^^^^^^^^^
  File "/opt/airflow/dags/oracle_dag.py", line 70, in load_data_to_oracle
    connection = oracle_hook.get_conn()
                 ^^^^^^^^^^^^^^^^^^^^^^
  File "/home/airflow/.local/lib/python3.12/site-packages/airflow/providers/oracle/hooks/oracle.py", line 237, in get_conn
    conn = oracledb.connect(**conn_config)
           ^^^^^^^^^^^^^^^^^^^^^^^^^^^^^^^
  File "/home/airflow/.local/lib/python3.12/site-packages/oracledb/connection.py", line 1169, in connect
    return conn_class(dsn=dsn, pool=pool, params=params, **kwargs)
           ^^^^^^^^^^^^^^^^^^^^^^^^^^^^^^^^^^^^^^^^^^^^^^^^^^^^^^^
  File "/home/airflow/.local/lib/python3.12/site-packages/oracledb/connection.py", line 551, in __init__
    impl.connect(params_impl)
  File "src/oracledb/impl/thin/connection.pyx", line 424, in oracledb.thin_impl.ThinConnImpl.connect
  File "src/oracledb/impl/thin/connection.pyx", line 420, in oracledb.thin_impl.ThinConnImpl.connect
  File "src/oracledb/impl/thin/connection.pyx", line 380, in oracledb.thin_impl.ThinConnImpl._connect_with_params
  File "src/oracledb/impl/thin/connection.pyx", line 361, in oracledb.thin_impl.ThinConnImpl._connect_with_description
  File "src/oracledb/impl/thin/connection.pyx", line 327, in oracledb.thin_impl.ThinConnImpl._connect_with_address
  File "/home/airflow/.local/lib/python3.12/site-packages/oracledb/errors.py", line 195, in _raise_err
    raise error.exc_type(error) from cause
oracledb.exceptions.OperationalError: DPY-6005: cannot connect to database (CONNECTION_ID=pmkh9og4GYTZTrf9RKgE9w==).
[Errno -5] No address associated with hostname
[2024-10-10T07:35:35.458+0000] {taskinstance.py:1206} INFO - Marking task as UP_FOR_RETRY. dag_id=import_excel_to_oracle_dag, task_id=import_kpi_template, run_id=manual__2024-10-10T07:35:30.741567+00:00, execution_date=20241010T073530, start_date=20241010T073534, end_date=20241010T073535
[2024-10-10T07:35:35.501+0000] {logging_mixin.py:188} WARNING - /home/***/.local/lib/python3.12/site-packages/***/utils/email.py:154 RemovedInAirflow3Warning: Fetching SMTP credentials from configuration variables will be deprecated in a future release. Please set credentials using a connection instead.
[2024-10-10T07:35:35.503+0000] {configuration.py:1053} WARNING - section/key [smtp/smtp_user] not found in config
[2024-10-10T07:35:35.505+0000] {email.py:271} INFO - Email alerting: attempt 1
[2024-10-10T07:35:35.529+0000] {configuration.py:1053} WARNING - section/key [smtp/smtp_user] not found in config
[2024-10-10T07:35:35.531+0000] {email.py:271} INFO - Email alerting: attempt 1
[2024-10-10T07:35:35.533+0000] {taskinstance.py:879} ERROR - Failed to send email to: ***
Traceback (most recent call last):
  File "src/oracledb/impl/thin/connection.pyx", line 322, in oracledb.thin_impl.ThinConnImpl._connect_with_address
  File "src/oracledb/impl/thin/protocol.pyx", line 225, in oracledb.thin_impl.Protocol._connect_phase_one
  File "src/oracledb/impl/thin/protocol.pyx", line 362, in oracledb.thin_impl.Protocol._connect_tcp
  File "/usr/local/lib/python3.12/socket.py", line 829, in create_connection
    for res in getaddrinfo(host, port, 0, SOCK_STREAM):
               ^^^^^^^^^^^^^^^^^^^^^^^^^^^^^^^^^^^^^^^
  File "/usr/local/lib/python3.12/socket.py", line 964, in getaddrinfo
    for res in _socket.getaddrinfo(host, port, family, type, proto, flags):
               ^^^^^^^^^^^^^^^^^^^^^^^^^^^^^^^^^^^^^^^^^^^^^^^^^^^^^^^^^^^
socket.gaierror: [Errno -5] No address associated with hostname

The above exception was the direct cause of the following exception:

Traceback (most recent call last):
  File "/home/airflow/.local/lib/python3.12/site-packages/airflow/models/taskinstance.py", line 2479, in _run_raw_task
    self._execute_task_with_callbacks(context, test_mode, session=session)
  File "/home/airflow/.local/lib/python3.12/site-packages/airflow/models/taskinstance.py", line 2676, in _execute_task_with_callbacks
    result = self._execute_task(context, task_orig)
             ^^^^^^^^^^^^^^^^^^^^^^^^^^^^^^^^^^^^^^
  File "/home/airflow/.local/lib/python3.12/site-packages/airflow/models/taskinstance.py", line 2701, in _execute_task
    return _execute_task(self, context, task_orig)
           ^^^^^^^^^^^^^^^^^^^^^^^^^^^^^^^^^^^^^^^
  File "/home/airflow/.local/lib/python3.12/site-packages/airflow/models/taskinstance.py", line 465, in _execute_task
    result = _execute_callable(context=context, **execute_callable_kwargs)
             ^^^^^^^^^^^^^^^^^^^^^^^^^^^^^^^^^^^^^^^^^^^^^^^^^^^^^^^^^^^^^
  File "/home/airflow/.local/lib/python3.12/site-packages/airflow/models/taskinstance.py", line 432, in _execute_callable
    return execute_callable(context=context, **execute_callable_kwargs)
           ^^^^^^^^^^^^^^^^^^^^^^^^^^^^^^^^^^^^^^^^^^^^^^^^^^^^^^^^^^^^
  File "/home/airflow/.local/lib/python3.12/site-packages/airflow/models/baseoperator.py", line 401, in wrapper
    return func(self, *args, **kwargs)
           ^^^^^^^^^^^^^^^^^^^^^^^^^^^
  File "/home/airflow/.local/lib/python3.12/site-packages/airflow/operators/python.py", line 235, in execute
    return_value = self.execute_callable()
                   ^^^^^^^^^^^^^^^^^^^^^^^
  File "/home/airflow/.local/lib/python3.12/site-packages/airflow/operators/python.py", line 252, in execute_callable
    return self.python_callable(*self.op_args, **self.op_kwargs)
           ^^^^^^^^^^^^^^^^^^^^^^^^^^^^^^^^^^^^^^^^^^^^^^^^^^^^^
  File "/opt/airflow/dags/oracle_dag.py", line 70, in load_data_to_oracle
    connection = oracle_hook.get_conn()
                 ^^^^^^^^^^^^^^^^^^^^^^
  File "/home/airflow/.local/lib/python3.12/site-packages/airflow/providers/oracle/hooks/oracle.py", line 237, in get_conn
    conn = oracledb.connect(**conn_config)
           ^^^^^^^^^^^^^^^^^^^^^^^^^^^^^^^
  File "/home/airflow/.local/lib/python3.12/site-packages/oracledb/connection.py", line 1169, in connect
    return conn_class(dsn=dsn, pool=pool, params=params, **kwargs)
           ^^^^^^^^^^^^^^^^^^^^^^^^^^^^^^^^^^^^^^^^^^^^^^^^^^^^^^^
  File "/home/airflow/.local/lib/python3.12/site-packages/oracledb/connection.py", line 551, in __init__
    impl.connect(params_impl)
  File "src/oracledb/impl/thin/connection.pyx", line 424, in oracledb.thin_impl.ThinConnImpl.connect
  File "src/oracledb/impl/thin/connection.pyx", line 420, in oracledb.thin_impl.ThinConnImpl.connect
  File "src/oracledb/impl/thin/connection.pyx", line 380, in oracledb.thin_impl.ThinConnImpl._connect_with_params
  File "src/oracledb/impl/thin/connection.pyx", line 361, in oracledb.thin_impl.ThinConnImpl._connect_with_description
  File "src/oracledb/impl/thin/connection.pyx", line 327, in oracledb.thin_impl.ThinConnImpl._connect_with_address
  File "/home/airflow/.local/lib/python3.12/site-packages/oracledb/errors.py", line 195, in _raise_err
    raise error.exc_type(error) from cause
oracledb.exceptions.OperationalError: DPY-6005: cannot connect to database (CONNECTION_ID=pmkh9og4GYTZTrf9RKgE9w==).
[Errno -5] No address associated with hostname

During handling of the above exception, another exception occurred:

Traceback (most recent call last):
  File "/home/airflow/.local/lib/python3.12/site-packages/airflow/models/taskinstance.py", line 1063, in _email_alert
    send_email(task.email, subject, html_content)
  File "/home/airflow/.local/lib/python3.12/site-packages/airflow/utils/email.py", line 80, in send_email
    return backend(
           ^^^^^^^^
  File "/home/airflow/.local/lib/python3.12/site-packages/airflow/utils/email.py", line 154, in send_email_smtp
    send_mime_email(e_from=mail_from, e_to=recipients, mime_msg=msg, conn_id=conn_id, dryrun=dryrun)
  File "/home/airflow/.local/lib/python3.12/site-packages/airflow/utils/email.py", line 273, in send_mime_email
    smtp_conn = _get_smtp_connection(smtp_host, smtp_port, smtp_timeout, smtp_ssl)
                ^^^^^^^^^^^^^^^^^^^^^^^^^^^^^^^^^^^^^^^^^^^^^^^^^^^^^^^^^^^^^^^^^^
  File "/home/airflow/.local/lib/python3.12/site-packages/airflow/utils/email.py", line 317, in _get_smtp_connection
    return smtplib.SMTP(host=host, port=port, timeout=timeout)
           ^^^^^^^^^^^^^^^^^^^^^^^^^^^^^^^^^^^^^^^^^^^^^^^^^^^
  File "/usr/local/lib/python3.12/smtplib.py", line 255, in __init__
    (code, msg) = self.connect(host, port)
                  ^^^^^^^^^^^^^^^^^^^^^^^^
  File "/usr/local/lib/python3.12/smtplib.py", line 341, in connect
    self.sock = self._get_socket(host, port, self.timeout)
                ^^^^^^^^^^^^^^^^^^^^^^^^^^^^^^^^^^^^^^^^^^
  File "/usr/local/lib/python3.12/smtplib.py", line 312, in _get_socket
    return socket.create_connection((host, port), timeout,
           ^^^^^^^^^^^^^^^^^^^^^^^^^^^^^^^^^^^^^^^^^^^^^^^
  File "/usr/local/lib/python3.12/socket.py", line 853, in create_connection
    raise exceptions[0]
  File "/usr/local/lib/python3.12/socket.py", line 838, in create_connection
    sock.connect(sa)
ConnectionRefusedError: [Errno 111] Connection refused

During handling of the above exception, another exception occurred:

Traceback (most recent call last):
  File "/home/airflow/.local/lib/python3.12/site-packages/airflow/models/taskinstance.py", line 877, in _handle_failure
    task_instance.email_alert(error, failure_context["task"])
  File "/home/airflow/.local/lib/python3.12/site-packages/airflow/models/taskinstance.py", line 3163, in email_alert
    _email_alert(task_instance=self, exception=exception, task=task)
  File "/home/airflow/.local/lib/python3.12/site-packages/airflow/models/taskinstance.py", line 1065, in _email_alert
    send_email(task.email, subject, html_content_err)
  File "/home/airflow/.local/lib/python3.12/site-packages/airflow/utils/email.py", line 80, in send_email
    return backend(
           ^^^^^^^^
  File "/home/airflow/.local/lib/python3.12/site-packages/airflow/utils/email.py", line 154, in send_email_smtp
    send_mime_email(e_from=mail_from, e_to=recipients, mime_msg=msg, conn_id=conn_id, dryrun=dryrun)
  File "/home/airflow/.local/lib/python3.12/site-packages/airflow/utils/email.py", line 273, in send_mime_email
    smtp_conn = _get_smtp_connection(smtp_host, smtp_port, smtp_timeout, smtp_ssl)
                ^^^^^^^^^^^^^^^^^^^^^^^^^^^^^^^^^^^^^^^^^^^^^^^^^^^^^^^^^^^^^^^^^^
  File "/home/airflow/.local/lib/python3.12/site-packages/airflow/utils/email.py", line 317, in _get_smtp_connection
    return smtplib.SMTP(host=host, port=port, timeout=timeout)
           ^^^^^^^^^^^^^^^^^^^^^^^^^^^^^^^^^^^^^^^^^^^^^^^^^^^
  File "/usr/local/lib/python3.12/smtplib.py", line 255, in __init__
    (code, msg) = self.connect(host, port)
                  ^^^^^^^^^^^^^^^^^^^^^^^^
  File "/usr/local/lib/python3.12/smtplib.py", line 341, in connect
    self.sock = self._get_socket(host, port, self.timeout)
                ^^^^^^^^^^^^^^^^^^^^^^^^^^^^^^^^^^^^^^^^^^
  File "/usr/local/lib/python3.12/smtplib.py", line 312, in _get_socket
    return socket.create_connection((host, port), timeout,
           ^^^^^^^^^^^^^^^^^^^^^^^^^^^^^^^^^^^^^^^^^^^^^^^
  File "/usr/local/lib/python3.12/socket.py", line 853, in create_connection
    raise exceptions[0]
  File "/usr/local/lib/python3.12/socket.py", line 838, in create_connection
    sock.connect(sa)
ConnectionRefusedError: [Errno 111] Connection refused
[2024-10-10T07:35:35.579+0000] {standard_task_runner.py:110} ERROR - Failed to execute job 23 for task import_kpi_template (DPY-6005: cannot connect to database (CONNECTION_ID=pmkh9og4GYTZTrf9RKgE9w==).
[Errno -5] No address associated with hostname; 316)
[2024-10-10T07:35:35.634+0000] {local_task_job_runner.py:243} INFO - Task exited with return code 1
[2024-10-10T07:35:35.700+0000] {taskinstance.py:3503} INFO - 0 downstream tasks scheduled from follow-on schedule check
[2024-10-10T07:35:35.711+0000] {local_task_job_runner.py:222} INFO - ::endgroup::
