[2024-10-03T03:27:40.843+0000] {local_task_job_runner.py:120} INFO - ::group::Pre task execution logs
[2024-10-03T03:27:40.907+0000] {taskinstance.py:2076} INFO - Dependencies all met for dep_context=non-requeueable deps ti=<TaskInstance: import_excel_to_oracle_dag.import_excel_to_oracle manual__2024-10-03T03:22:33.121772+00:00 [queued]>
[2024-10-03T03:27:40.926+0000] {taskinstance.py:2076} INFO - Dependencies all met for dep_context=requeueable deps ti=<TaskInstance: import_excel_to_oracle_dag.import_excel_to_oracle manual__2024-10-03T03:22:33.121772+00:00 [queued]>
[2024-10-03T03:27:40.927+0000] {taskinstance.py:2306} INFO - Starting attempt 2 of 2
[2024-10-03T03:27:40.959+0000] {taskinstance.py:2330} INFO - Executing <Task(PythonOperator): import_excel_to_oracle> on 2024-10-03 03:22:33.121772+00:00
[2024-10-03T03:27:40.978+0000] {logging_mixin.py:188} WARNING - /home/***/.local/lib/python3.12/site-packages/***/task/task_runner/standard_task_runner.py:62 DeprecationWarning: This process (pid=32596) is multi-threaded, use of fork() may lead to deadlocks in the child.
[2024-10-03T03:27:40.975+0000] {standard_task_runner.py:90} INFO - Running: ['***', 'tasks', 'run', 'import_excel_to_oracle_dag', 'import_excel_to_oracle', 'manual__2024-10-03T03:22:33.121772+00:00', '--job-id', '13', '--raw', '--subdir', 'DAGS_FOLDER/new_dag.py', '--cfg-path', '/tmp/tmplkx48sfo']
[2024-10-03T03:27:40.980+0000] {standard_task_runner.py:64} INFO - Started process 32605 to run task
[2024-10-03T03:27:40.980+0000] {standard_task_runner.py:91} INFO - Job 13: Subtask import_excel_to_oracle
[2024-10-03T03:27:41.010+0000] {logging_mixin.py:188} WARNING - /home/***/.local/lib/python3.12/site-packages/***/settings.py:195 DeprecationWarning: The sql_alchemy_conn option in [core] has been moved to the sql_alchemy_conn option in [database] - the old setting has been used, but please update your config.
[2024-10-03T03:27:41.083+0000] {task_command.py:426} INFO - Running <TaskInstance: import_excel_to_oracle_dag.import_excel_to_oracle manual__2024-10-03T03:22:33.121772+00:00 [running]> on host 3fed06331d8d
[2024-10-03T03:27:41.264+0000] {taskinstance.py:2648} INFO - Exporting env vars: AIRFLOW_CTX_DAG_EMAIL='admin' AIRFLOW_CTX_DAG_OWNER='***' AIRFLOW_CTX_DAG_ID='import_excel_to_oracle_dag' AIRFLOW_CTX_TASK_ID='import_excel_to_oracle' AIRFLOW_CTX_EXECUTION_DATE='2024-10-03T03:22:33.121772+00:00' AIRFLOW_CTX_TRY_NUMBER='2' AIRFLOW_CTX_DAG_RUN_ID='manual__2024-10-03T03:22:33.121772+00:00'
[2024-10-03T03:27:41.266+0000] {taskinstance.py:430} INFO - ::endgroup::
[2024-10-03T03:27:41.314+0000] {base.py:84} INFO - Using connection ID 'oracle_conn_id' for task execution.
[2024-10-03T03:27:41.317+0000] {taskinstance.py:441} INFO - ::group::Post task execution logs
[2024-10-03T03:27:41.319+0000] {taskinstance.py:2905} ERROR - Task failed with exception
Traceback (most recent call last):
  File "src/oracledb/impl/thin/connection.pyx", line 322, in oracledb.thin_impl.ThinConnImpl._connect_with_address
  File "src/oracledb/impl/thin/protocol.pyx", line 225, in oracledb.thin_impl.Protocol._connect_phase_one
  File "src/oracledb/impl/thin/protocol.pyx", line 362, in oracledb.thin_impl.Protocol._connect_tcp
  File "/usr/local/lib/python3.12/socket.py", line 853, in create_connection
    raise exceptions[0]
  File "/usr/local/lib/python3.12/socket.py", line 838, in create_connection
    sock.connect(sa)
ConnectionRefusedError: [Errno 111] Connection refused

The above exception was the direct cause of the following exception:

Traceback (most recent call last):
  File "/home/airflow/.local/lib/python3.12/site-packages/airflow/models/taskinstance.py", line 465, in _execute_task
    result = _execute_callable(context=context, **execute_callable_kwargs)
             ^^^^^^^^^^^^^^^^^^^^^^^^^^^^^^^^^^^^^^^^^^^^^^^^^^^^^^^^^^^^^
  File "/home/airflow/.local/lib/python3.12/site-packages/airflow/models/taskinstance.py", line 432, in _execute_callable
    return execute_callable(context=context, **execute_callable_kwargs)
           ^^^^^^^^^^^^^^^^^^^^^^^^^^^^^^^^^^^^^^^^^^^^^^^^^^^^^^^^^^^^
  File "/home/airflow/.local/lib/python3.12/site-packages/airflow/models/baseoperator.py", line 401, in wrapper
    return func(self, *args, **kwargs)
           ^^^^^^^^^^^^^^^^^^^^^^^^^^^
  File "/home/airflow/.local/lib/python3.12/site-packages/airflow/operators/python.py", line 235, in execute
    return_value = self.execute_callable()
                   ^^^^^^^^^^^^^^^^^^^^^^^
  File "/home/airflow/.local/lib/python3.12/site-packages/airflow/operators/python.py", line 252, in execute_callable
    return self.python_callable(*self.op_args, **self.op_kwargs)
           ^^^^^^^^^^^^^^^^^^^^^^^^^^^^^^^^^^^^^^^^^^^^^^^^^^^^^
  File "/opt/airflow/dags/new_dag.py", line 47, in load_data_to_oracle
    conn = oracle_hook.get_conn()
           ^^^^^^^^^^^^^^^^^^^^^^
  File "/home/airflow/.local/lib/python3.12/site-packages/airflow/providers/oracle/hooks/oracle.py", line 237, in get_conn
    conn = oracledb.connect(**conn_config)
           ^^^^^^^^^^^^^^^^^^^^^^^^^^^^^^^
  File "/home/airflow/.local/lib/python3.12/site-packages/oracledb/connection.py", line 1169, in connect
    return conn_class(dsn=dsn, pool=pool, params=params, **kwargs)
           ^^^^^^^^^^^^^^^^^^^^^^^^^^^^^^^^^^^^^^^^^^^^^^^^^^^^^^^
  File "/home/airflow/.local/lib/python3.12/site-packages/oracledb/connection.py", line 551, in __init__
    impl.connect(params_impl)
  File "src/oracledb/impl/thin/connection.pyx", line 424, in oracledb.thin_impl.ThinConnImpl.connect
  File "src/oracledb/impl/thin/connection.pyx", line 420, in oracledb.thin_impl.ThinConnImpl.connect
  File "src/oracledb/impl/thin/connection.pyx", line 380, in oracledb.thin_impl.ThinConnImpl._connect_with_params
  File "src/oracledb/impl/thin/connection.pyx", line 361, in oracledb.thin_impl.ThinConnImpl._connect_with_description
  File "src/oracledb/impl/thin/connection.pyx", line 327, in oracledb.thin_impl.ThinConnImpl._connect_with_address
  File "/home/airflow/.local/lib/python3.12/site-packages/oracledb/errors.py", line 195, in _raise_err
    raise error.exc_type(error) from cause
oracledb.exceptions.OperationalError: DPY-6005: cannot connect to database (CONNECTION_ID=v8iiybCCtL9j3CCd5GnFmQ==).
[Errno 111] Connection refused
[2024-10-03T03:27:41.356+0000] {taskinstance.py:1206} INFO - Marking task as FAILED. dag_id=import_excel_to_oracle_dag, task_id=import_excel_to_oracle, run_id=manual__2024-10-03T03:22:33.121772+00:00, execution_date=20241003T032233, start_date=20241003T032740, end_date=20241003T032741
[2024-10-03T03:27:41.385+0000] {logging_mixin.py:188} WARNING - /home/***/.local/lib/python3.12/site-packages/***/utils/email.py:154 RemovedInAirflow3Warning: Fetching SMTP credentials from configuration variables will be deprecated in a future release. Please set credentials using a connection instead.
[2024-10-03T03:27:41.387+0000] {configuration.py:1053} WARNING - section/key [smtp/smtp_user] not found in config
[2024-10-03T03:27:41.389+0000] {email.py:271} INFO - Email alerting: attempt 1
[2024-10-03T03:27:41.403+0000] {configuration.py:1053} WARNING - section/key [smtp/smtp_user] not found in config
[2024-10-03T03:27:41.405+0000] {email.py:271} INFO - Email alerting: attempt 1
[2024-10-03T03:27:41.407+0000] {taskinstance.py:879} ERROR - Failed to send email to: admin
Traceback (most recent call last):
  File "src/oracledb/impl/thin/connection.pyx", line 322, in oracledb.thin_impl.ThinConnImpl._connect_with_address
  File "src/oracledb/impl/thin/protocol.pyx", line 225, in oracledb.thin_impl.Protocol._connect_phase_one
  File "src/oracledb/impl/thin/protocol.pyx", line 362, in oracledb.thin_impl.Protocol._connect_tcp
  File "/usr/local/lib/python3.12/socket.py", line 853, in create_connection
    raise exceptions[0]
  File "/usr/local/lib/python3.12/socket.py", line 838, in create_connection
    sock.connect(sa)
ConnectionRefusedError: [Errno 111] Connection refused

The above exception was the direct cause of the following exception:

Traceback (most recent call last):
  File "/home/airflow/.local/lib/python3.12/site-packages/airflow/models/taskinstance.py", line 2479, in _run_raw_task
    self._execute_task_with_callbacks(context, test_mode, session=session)
  File "/home/airflow/.local/lib/python3.12/site-packages/airflow/models/taskinstance.py", line 2676, in _execute_task_with_callbacks
    result = self._execute_task(context, task_orig)
             ^^^^^^^^^^^^^^^^^^^^^^^^^^^^^^^^^^^^^^
  File "/home/airflow/.local/lib/python3.12/site-packages/airflow/models/taskinstance.py", line 2701, in _execute_task
    return _execute_task(self, context, task_orig)
           ^^^^^^^^^^^^^^^^^^^^^^^^^^^^^^^^^^^^^^^
  File "/home/airflow/.local/lib/python3.12/site-packages/airflow/models/taskinstance.py", line 465, in _execute_task
    result = _execute_callable(context=context, **execute_callable_kwargs)
             ^^^^^^^^^^^^^^^^^^^^^^^^^^^^^^^^^^^^^^^^^^^^^^^^^^^^^^^^^^^^^
  File "/home/airflow/.local/lib/python3.12/site-packages/airflow/models/taskinstance.py", line 432, in _execute_callable
    return execute_callable(context=context, **execute_callable_kwargs)
           ^^^^^^^^^^^^^^^^^^^^^^^^^^^^^^^^^^^^^^^^^^^^^^^^^^^^^^^^^^^^
  File "/home/airflow/.local/lib/python3.12/site-packages/airflow/models/baseoperator.py", line 401, in wrapper
    return func(self, *args, **kwargs)
           ^^^^^^^^^^^^^^^^^^^^^^^^^^^
  File "/home/airflow/.local/lib/python3.12/site-packages/airflow/operators/python.py", line 235, in execute
    return_value = self.execute_callable()
                   ^^^^^^^^^^^^^^^^^^^^^^^
  File "/home/airflow/.local/lib/python3.12/site-packages/airflow/operators/python.py", line 252, in execute_callable
    return self.python_callable(*self.op_args, **self.op_kwargs)
           ^^^^^^^^^^^^^^^^^^^^^^^^^^^^^^^^^^^^^^^^^^^^^^^^^^^^^
  File "/opt/airflow/dags/new_dag.py", line 47, in load_data_to_oracle
    conn = oracle_hook.get_conn()
           ^^^^^^^^^^^^^^^^^^^^^^
  File "/home/airflow/.local/lib/python3.12/site-packages/airflow/providers/oracle/hooks/oracle.py", line 237, in get_conn
    conn = oracledb.connect(**conn_config)
           ^^^^^^^^^^^^^^^^^^^^^^^^^^^^^^^
  File "/home/airflow/.local/lib/python3.12/site-packages/oracledb/connection.py", line 1169, in connect
    return conn_class(dsn=dsn, pool=pool, params=params, **kwargs)
           ^^^^^^^^^^^^^^^^^^^^^^^^^^^^^^^^^^^^^^^^^^^^^^^^^^^^^^^
  File "/home/airflow/.local/lib/python3.12/site-packages/oracledb/connection.py", line 551, in __init__
    impl.connect(params_impl)
  File "src/oracledb/impl/thin/connection.pyx", line 424, in oracledb.thin_impl.ThinConnImpl.connect
  File "src/oracledb/impl/thin/connection.pyx", line 420, in oracledb.thin_impl.ThinConnImpl.connect
  File "src/oracledb/impl/thin/connection.pyx", line 380, in oracledb.thin_impl.ThinConnImpl._connect_with_params
  File "src/oracledb/impl/thin/connection.pyx", line 361, in oracledb.thin_impl.ThinConnImpl._connect_with_description
  File "src/oracledb/impl/thin/connection.pyx", line 327, in oracledb.thin_impl.ThinConnImpl._connect_with_address
  File "/home/airflow/.local/lib/python3.12/site-packages/oracledb/errors.py", line 195, in _raise_err
    raise error.exc_type(error) from cause
oracledb.exceptions.OperationalError: DPY-6005: cannot connect to database (CONNECTION_ID=v8iiybCCtL9j3CCd5GnFmQ==).
[Errno 111] Connection refused

During handling of the above exception, another exception occurred:

Traceback (most recent call last):
  File "/home/airflow/.local/lib/python3.12/site-packages/airflow/models/taskinstance.py", line 1063, in _email_alert
    send_email(task.email, subject, html_content)
  File "/home/airflow/.local/lib/python3.12/site-packages/airflow/utils/email.py", line 80, in send_email
    return backend(
           ^^^^^^^^
  File "/home/airflow/.local/lib/python3.12/site-packages/airflow/utils/email.py", line 154, in send_email_smtp
    send_mime_email(e_from=mail_from, e_to=recipients, mime_msg=msg, conn_id=conn_id, dryrun=dryrun)
  File "/home/airflow/.local/lib/python3.12/site-packages/airflow/utils/email.py", line 273, in send_mime_email
    smtp_conn = _get_smtp_connection(smtp_host, smtp_port, smtp_timeout, smtp_ssl)
                ^^^^^^^^^^^^^^^^^^^^^^^^^^^^^^^^^^^^^^^^^^^^^^^^^^^^^^^^^^^^^^^^^^
  File "/home/airflow/.local/lib/python3.12/site-packages/airflow/utils/email.py", line 317, in _get_smtp_connection
    return smtplib.SMTP(host=host, port=port, timeout=timeout)
           ^^^^^^^^^^^^^^^^^^^^^^^^^^^^^^^^^^^^^^^^^^^^^^^^^^^
  File "/usr/local/lib/python3.12/smtplib.py", line 255, in __init__
    (code, msg) = self.connect(host, port)
                  ^^^^^^^^^^^^^^^^^^^^^^^^
  File "/usr/local/lib/python3.12/smtplib.py", line 341, in connect
    self.sock = self._get_socket(host, port, self.timeout)
                ^^^^^^^^^^^^^^^^^^^^^^^^^^^^^^^^^^^^^^^^^^
  File "/usr/local/lib/python3.12/smtplib.py", line 312, in _get_socket
    return socket.create_connection((host, port), timeout,
           ^^^^^^^^^^^^^^^^^^^^^^^^^^^^^^^^^^^^^^^^^^^^^^^
  File "/usr/local/lib/python3.12/socket.py", line 853, in create_connection
    raise exceptions[0]
  File "/usr/local/lib/python3.12/socket.py", line 838, in create_connection
    sock.connect(sa)
ConnectionRefusedError: [Errno 111] Connection refused

During handling of the above exception, another exception occurred:

Traceback (most recent call last):
  File "/home/airflow/.local/lib/python3.12/site-packages/airflow/models/taskinstance.py", line 877, in _handle_failure
    task_instance.email_alert(error, failure_context["task"])
  File "/home/airflow/.local/lib/python3.12/site-packages/airflow/models/taskinstance.py", line 3163, in email_alert
    _email_alert(task_instance=self, exception=exception, task=task)
  File "/home/airflow/.local/lib/python3.12/site-packages/airflow/models/taskinstance.py", line 1065, in _email_alert
    send_email(task.email, subject, html_content_err)
  File "/home/airflow/.local/lib/python3.12/site-packages/airflow/utils/email.py", line 80, in send_email
    return backend(
           ^^^^^^^^
  File "/home/airflow/.local/lib/python3.12/site-packages/airflow/utils/email.py", line 154, in send_email_smtp
    send_mime_email(e_from=mail_from, e_to=recipients, mime_msg=msg, conn_id=conn_id, dryrun=dryrun)
  File "/home/airflow/.local/lib/python3.12/site-packages/airflow/utils/email.py", line 273, in send_mime_email
    smtp_conn = _get_smtp_connection(smtp_host, smtp_port, smtp_timeout, smtp_ssl)
                ^^^^^^^^^^^^^^^^^^^^^^^^^^^^^^^^^^^^^^^^^^^^^^^^^^^^^^^^^^^^^^^^^^
  File "/home/airflow/.local/lib/python3.12/site-packages/airflow/utils/email.py", line 317, in _get_smtp_connection
    return smtplib.SMTP(host=host, port=port, timeout=timeout)
           ^^^^^^^^^^^^^^^^^^^^^^^^^^^^^^^^^^^^^^^^^^^^^^^^^^^
  File "/usr/local/lib/python3.12/smtplib.py", line 255, in __init__
    (code, msg) = self.connect(host, port)
                  ^^^^^^^^^^^^^^^^^^^^^^^^
  File "/usr/local/lib/python3.12/smtplib.py", line 341, in connect
    self.sock = self._get_socket(host, port, self.timeout)
                ^^^^^^^^^^^^^^^^^^^^^^^^^^^^^^^^^^^^^^^^^^
  File "/usr/local/lib/python3.12/smtplib.py", line 312, in _get_socket
    return socket.create_connection((host, port), timeout,
           ^^^^^^^^^^^^^^^^^^^^^^^^^^^^^^^^^^^^^^^^^^^^^^^
  File "/usr/local/lib/python3.12/socket.py", line 853, in create_connection
    raise exceptions[0]
  File "/usr/local/lib/python3.12/socket.py", line 838, in create_connection
    sock.connect(sa)
ConnectionRefusedError: [Errno 111] Connection refused
[2024-10-03T03:27:41.444+0000] {standard_task_runner.py:110} ERROR - Failed to execute job 13 for task import_excel_to_oracle (DPY-6005: cannot connect to database (CONNECTION_ID=v8iiybCCtL9j3CCd5GnFmQ==).
[Errno 111] Connection refused; 32605)
[2024-10-03T03:27:41.478+0000] {local_task_job_runner.py:243} INFO - Task exited with return code 1
[2024-10-03T03:27:41.518+0000] {taskinstance.py:3503} INFO - 0 downstream tasks scheduled from follow-on schedule check
[2024-10-03T03:27:41.525+0000] {local_task_job_runner.py:222} INFO - ::endgroup::
