[2024-10-04T17:19:12.240+0000] {local_task_job_runner.py:120} INFO - ::group::Pre task execution logs
[2024-10-04T17:19:12.303+0000] {taskinstance.py:2076} INFO - Dependencies all met for dep_context=non-requeueable deps ti=<TaskInstance: api_to_json_dag.call_api_task scheduled__2024-10-03T00:00:00+00:00 [queued]>
[2024-10-04T17:19:12.323+0000] {taskinstance.py:2076} INFO - Dependencies all met for dep_context=requeueable deps ti=<TaskInstance: api_to_json_dag.call_api_task scheduled__2024-10-03T00:00:00+00:00 [queued]>
[2024-10-04T17:19:12.325+0000] {taskinstance.py:2306} INFO - Starting attempt 2 of 2
[2024-10-04T17:19:12.361+0000] {taskinstance.py:2330} INFO - Executing <Task(BashOperator): call_api_task> on 2024-10-03 00:00:00+00:00
[2024-10-04T17:19:12.373+0000] {logging_mixin.py:188} WARNING - /home/***/.local/lib/python3.12/site-packages/***/task/task_runner/standard_task_runner.py:62 DeprecationWarning: This process (pid=2324) is multi-threaded, use of fork() may lead to deadlocks in the child.
[2024-10-04T17:19:12.377+0000] {standard_task_runner.py:64} INFO - Started process 2325 to run task
[2024-10-04T17:19:12.373+0000] {standard_task_runner.py:90} INFO - Running: ['***', 'tasks', 'run', 'api_to_json_dag', 'call_api_task', 'scheduled__2024-10-03T00:00:00+00:00', '--job-id', '51', '--raw', '--subdir', 'DAGS_FOLDER/dag_to_api.py', '--cfg-path', '/tmp/tmp_taf7fg_']
[2024-10-04T17:19:12.379+0000] {standard_task_runner.py:91} INFO - Job 51: Subtask call_api_task
[2024-10-04T17:19:12.416+0000] {logging_mixin.py:188} WARNING - /home/***/.local/lib/python3.12/site-packages/***/settings.py:195 DeprecationWarning: The sql_alchemy_conn option in [core] has been moved to the sql_alchemy_conn option in [database] - the old setting has been used, but please update your config.
[2024-10-04T17:19:12.505+0000] {task_command.py:426} INFO - Running <TaskInstance: api_to_json_dag.call_api_task scheduled__2024-10-03T00:00:00+00:00 [running]> on host 3fed06331d8d
[2024-10-04T17:19:12.704+0000] {taskinstance.py:2648} INFO - Exporting env vars: AIRFLOW_CTX_DAG_OWNER='***' AIRFLOW_CTX_DAG_ID='api_to_json_dag' AIRFLOW_CTX_TASK_ID='call_api_task' AIRFLOW_CTX_EXECUTION_DATE='2024-10-03T00:00:00+00:00' AIRFLOW_CTX_TRY_NUMBER='2' AIRFLOW_CTX_DAG_RUN_ID='scheduled__2024-10-03T00:00:00+00:00'
[2024-10-04T17:19:12.706+0000] {taskinstance.py:430} INFO - ::endgroup::
[2024-10-04T17:19:12.740+0000] {subprocess.py:63} INFO - Tmp dir root location: /tmp
[2024-10-04T17:19:12.743+0000] {subprocess.py:75} INFO - Running command: ['/usr/bin/bash', '-c', 'python call_api.py']
[2024-10-04T17:19:12.755+0000] {subprocess.py:86} INFO - Output:
[2024-10-04T17:19:12.785+0000] {subprocess.py:93} INFO - python: can't open file '/tmp/***tmpaz600te8/call_api.py': [Errno 2] No such file or directory
[2024-10-04T17:19:12.790+0000] {subprocess.py:97} INFO - Command exited with return code 2
[2024-10-04T17:19:12.792+0000] {taskinstance.py:441} INFO - ::group::Post task execution logs
[2024-10-04T17:19:12.813+0000] {taskinstance.py:2905} ERROR - Task failed with exception
Traceback (most recent call last):
  File "/home/airflow/.local/lib/python3.12/site-packages/airflow/models/taskinstance.py", line 465, in _execute_task
    result = _execute_callable(context=context, **execute_callable_kwargs)
             ^^^^^^^^^^^^^^^^^^^^^^^^^^^^^^^^^^^^^^^^^^^^^^^^^^^^^^^^^^^^^
  File "/home/airflow/.local/lib/python3.12/site-packages/airflow/models/taskinstance.py", line 432, in _execute_callable
    return execute_callable(context=context, **execute_callable_kwargs)
           ^^^^^^^^^^^^^^^^^^^^^^^^^^^^^^^^^^^^^^^^^^^^^^^^^^^^^^^^^^^^
  File "/home/airflow/.local/lib/python3.12/site-packages/airflow/models/baseoperator.py", line 401, in wrapper
    return func(self, *args, **kwargs)
           ^^^^^^^^^^^^^^^^^^^^^^^^^^^
  File "/home/airflow/.local/lib/python3.12/site-packages/airflow/operators/bash.py", line 243, in execute
    raise AirflowException(
airflow.exceptions.AirflowException: Bash command failed. The command returned a non-zero exit code 2.
[2024-10-04T17:19:12.823+0000] {taskinstance.py:1206} INFO - Marking task as FAILED. dag_id=api_to_json_dag, task_id=call_api_task, run_id=scheduled__2024-10-03T00:00:00+00:00, execution_date=20241003T000000, start_date=20241004T171912, end_date=20241004T171912
[2024-10-04T17:19:12.858+0000] {standard_task_runner.py:110} ERROR - Failed to execute job 51 for task call_api_task (Bash command failed. The command returned a non-zero exit code 2.; 2325)
[2024-10-04T17:19:12.875+0000] {local_task_job_runner.py:243} INFO - Task exited with return code 1
[2024-10-04T17:19:12.917+0000] {taskinstance.py:3503} INFO - 0 downstream tasks scheduled from follow-on schedule check
[2024-10-04T17:19:12.924+0000] {local_task_job_runner.py:222} INFO - ::endgroup::
