[2024-10-11T01:40:22.039+0000] {local_task_job_runner.py:120} INFO - ::group::Pre task execution logs
[2024-10-11T01:40:22.337+0000] {taskinstance.py:2076} INFO - Dependencies all met for dep_context=non-requeueable deps ti=<TaskInstance: api_dag.is_api_active scheduled__2024-10-10T00:00:00+00:00 [queued]>
[2024-10-11T01:40:22.476+0000] {taskinstance.py:2076} INFO - Dependencies all met for dep_context=requeueable deps ti=<TaskInstance: api_dag.is_api_active scheduled__2024-10-10T00:00:00+00:00 [queued]>
[2024-10-11T01:40:22.498+0000] {taskinstance.py:2306} INFO - Starting attempt 1 of 1
[2024-10-11T01:40:22.814+0000] {taskinstance.py:2330} INFO - Executing <Task(HttpSensor): is_api_active> on 2024-10-10 00:00:00+00:00
[2024-10-11T01:40:22.877+0000] {standard_task_runner.py:90} INFO - Running: ['***', 'tasks', 'run', 'api_dag', 'is_api_active', 'scheduled__2024-10-10T00:00:00+00:00', '--job-id', '114', '--raw', '--subdir', 'DAGS_FOLDER/api_dag.py', '--cfg-path', '/tmp/tmp9dkfqo66']
[2024-10-11T01:40:22.900+0000] {standard_task_runner.py:91} INFO - Job 114: Subtask is_api_active
[2024-10-11T01:40:22.890+0000] {logging_mixin.py:188} WARNING - /home/***/.local/lib/python3.12/site-packages/***/task/task_runner/standard_task_runner.py:62 DeprecationWarning: This process (pid=7724) is multi-threaded, use of fork() may lead to deadlocks in the child.
[2024-10-11T01:40:22.939+0000] {standard_task_runner.py:64} INFO - Started process 7725 to run task
[2024-10-11T01:40:22.996+0000] {logging_mixin.py:188} WARNING - /home/***/.local/lib/python3.12/site-packages/***/settings.py:195 DeprecationWarning: The sql_alchemy_conn option in [core] has been moved to the sql_alchemy_conn option in [database] - the old setting has been used, but please update your config.
[2024-10-11T01:40:23.196+0000] {task_command.py:426} INFO - Running <TaskInstance: api_dag.is_api_active scheduled__2024-10-10T00:00:00+00:00 [running]> on host 751c06a3cc64
[2024-10-11T01:40:23.872+0000] {taskinstance.py:2648} INFO - Exporting env vars: AIRFLOW_CTX_DAG_OWNER='***' AIRFLOW_CTX_DAG_ID='api_dag' AIRFLOW_CTX_TASK_ID='is_api_active' AIRFLOW_CTX_EXECUTION_DATE='2024-10-10T00:00:00+00:00' AIRFLOW_CTX_TRY_NUMBER='1' AIRFLOW_CTX_DAG_RUN_ID='scheduled__2024-10-10T00:00:00+00:00'
[2024-10-11T01:40:23.908+0000] {taskinstance.py:430} INFO - ::endgroup::
[2024-10-11T01:40:24.091+0000] {baseoperator.py:400} WARNING - HttpSensor.execute cannot be called outside TaskInstance!
[2024-10-11T01:40:24.104+0000] {http.py:137} INFO - Poking: posts/
[2024-10-11T01:40:24.147+0000] {base.py:84} INFO - Using connection ID 'http_default' for task execution.
[2024-10-11T01:40:24.750+0000] {http.py:243} WARNING - HTTPSConnectionPool(host='gorest.co.in', port=443): Max retries exceeded with url: /public/v2/posts/ (Caused by NameResolutionError("<urllib3.connection.HTTPSConnection object at 0x7fc7a8d318b0>: Failed to resolve 'gorest.co.in' ([Errno -2] Name or service not known)")) Tenacity will retry to execute the operation
[2024-10-11T01:40:24.758+0000] {taskinstance.py:441} INFO - ::group::Post task execution logs
[2024-10-11T01:40:24.775+0000] {taskinstance.py:2905} ERROR - Task failed with exception
Traceback (most recent call last):
  File "/home/airflow/.local/lib/python3.12/site-packages/urllib3/connection.py", line 203, in _new_conn
    sock = connection.create_connection(
           ^^^^^^^^^^^^^^^^^^^^^^^^^^^^^
  File "/home/airflow/.local/lib/python3.12/site-packages/urllib3/util/connection.py", line 60, in create_connection
    for res in socket.getaddrinfo(host, port, family, socket.SOCK_STREAM):
               ^^^^^^^^^^^^^^^^^^^^^^^^^^^^^^^^^^^^^^^^^^^^^^^^^^^^^^^^^^
  File "/usr/local/lib/python3.12/socket.py", line 964, in getaddrinfo
    for res in _socket.getaddrinfo(host, port, family, type, proto, flags):
               ^^^^^^^^^^^^^^^^^^^^^^^^^^^^^^^^^^^^^^^^^^^^^^^^^^^^^^^^^^^
socket.gaierror: [Errno -2] Name or service not known

The above exception was the direct cause of the following exception:

Traceback (most recent call last):
  File "/home/airflow/.local/lib/python3.12/site-packages/urllib3/connectionpool.py", line 791, in urlopen
    response = self._make_request(
               ^^^^^^^^^^^^^^^^^^^
  File "/home/airflow/.local/lib/python3.12/site-packages/urllib3/connectionpool.py", line 492, in _make_request
    raise new_e
  File "/home/airflow/.local/lib/python3.12/site-packages/urllib3/connectionpool.py", line 468, in _make_request
    self._validate_conn(conn)
  File "/home/airflow/.local/lib/python3.12/site-packages/urllib3/connectionpool.py", line 1097, in _validate_conn
    conn.connect()
  File "/home/airflow/.local/lib/python3.12/site-packages/urllib3/connection.py", line 611, in connect
    self.sock = sock = self._new_conn()
                       ^^^^^^^^^^^^^^^^
  File "/home/airflow/.local/lib/python3.12/site-packages/urllib3/connection.py", line 210, in _new_conn
    raise NameResolutionError(self.host, self, e) from e
urllib3.exceptions.NameResolutionError: <urllib3.connection.HTTPSConnection object at 0x7fc7a8d318b0>: Failed to resolve 'gorest.co.in' ([Errno -2] Name or service not known)

The above exception was the direct cause of the following exception:

Traceback (most recent call last):
  File "/home/airflow/.local/lib/python3.12/site-packages/requests/adapters.py", line 667, in send
    resp = conn.urlopen(
           ^^^^^^^^^^^^^
  File "/home/airflow/.local/lib/python3.12/site-packages/urllib3/connectionpool.py", line 845, in urlopen
    retries = retries.increment(
              ^^^^^^^^^^^^^^^^^^
  File "/home/airflow/.local/lib/python3.12/site-packages/urllib3/util/retry.py", line 515, in increment
    raise MaxRetryError(_pool, url, reason) from reason  # type: ignore[arg-type]
    ^^^^^^^^^^^^^^^^^^^^^^^^^^^^^^^^^^^^^^^^^^^^^^^^^^^
urllib3.exceptions.MaxRetryError: HTTPSConnectionPool(host='gorest.co.in', port=443): Max retries exceeded with url: /public/v2/posts/ (Caused by NameResolutionError("<urllib3.connection.HTTPSConnection object at 0x7fc7a8d318b0>: Failed to resolve 'gorest.co.in' ([Errno -2] Name or service not known)"))

During handling of the above exception, another exception occurred:

Traceback (most recent call last):
  File "/home/airflow/.local/lib/python3.12/site-packages/airflow/models/taskinstance.py", line 465, in _execute_task
    result = _execute_callable(context=context, **execute_callable_kwargs)
             ^^^^^^^^^^^^^^^^^^^^^^^^^^^^^^^^^^^^^^^^^^^^^^^^^^^^^^^^^^^^^
  File "/home/airflow/.local/lib/python3.12/site-packages/airflow/models/taskinstance.py", line 432, in _execute_callable
    return execute_callable(context=context, **execute_callable_kwargs)
           ^^^^^^^^^^^^^^^^^^^^^^^^^^^^^^^^^^^^^^^^^^^^^^^^^^^^^^^^^^^^
  File "/home/airflow/.local/lib/python3.12/site-packages/airflow/models/baseoperator.py", line 401, in wrapper
    return func(self, *args, **kwargs)
           ^^^^^^^^^^^^^^^^^^^^^^^^^^^
  File "/home/airflow/.local/lib/python3.12/site-packages/airflow/providers/http/sensors/http.py", line 164, in execute
    super().execute(context=context)
  File "/home/airflow/.local/lib/python3.12/site-packages/airflow/models/baseoperator.py", line 401, in wrapper
    return func(self, *args, **kwargs)
           ^^^^^^^^^^^^^^^^^^^^^^^^^^^
  File "/home/airflow/.local/lib/python3.12/site-packages/airflow/sensors/base.py", line 264, in execute
    raise e
  File "/home/airflow/.local/lib/python3.12/site-packages/airflow/sensors/base.py", line 246, in execute
    poke_return = self.poke(context)
                  ^^^^^^^^^^^^^^^^^^
  File "/home/airflow/.local/lib/python3.12/site-packages/airflow/providers/http/sensors/http.py", line 139, in poke
    response = hook.run(
               ^^^^^^^^^
  File "/home/airflow/.local/lib/python3.12/site-packages/airflow/providers/http/hooks/http.py", line 188, in run
    return self.run_and_check(session, prepped_request, extra_options)
           ^^^^^^^^^^^^^^^^^^^^^^^^^^^^^^^^^^^^^^^^^^^^^^^^^^^^^^^^^^^
  File "/home/airflow/.local/lib/python3.12/site-packages/airflow/providers/http/hooks/http.py", line 244, in run_and_check
    raise ex
  File "/home/airflow/.local/lib/python3.12/site-packages/airflow/providers/http/hooks/http.py", line 236, in run_and_check
    response = session.send(prepped_request, **send_kwargs)
               ^^^^^^^^^^^^^^^^^^^^^^^^^^^^^^^^^^^^^^^^^^^^
  File "/home/airflow/.local/lib/python3.12/site-packages/requests/sessions.py", line 703, in send
    r = adapter.send(request, **kwargs)
        ^^^^^^^^^^^^^^^^^^^^^^^^^^^^^^^
  File "/home/airflow/.local/lib/python3.12/site-packages/requests/adapters.py", line 700, in send
    raise ConnectionError(e, request=request)
requests.exceptions.ConnectionError: HTTPSConnectionPool(host='gorest.co.in', port=443): Max retries exceeded with url: /public/v2/posts/ (Caused by NameResolutionError("<urllib3.connection.HTTPSConnection object at 0x7fc7a8d318b0>: Failed to resolve 'gorest.co.in' ([Errno -2] Name or service not known)"))
[2024-10-11T01:40:24.883+0000] {taskinstance.py:1206} INFO - Marking task as FAILED. dag_id=api_dag, task_id=is_api_active, run_id=scheduled__2024-10-10T00:00:00+00:00, execution_date=20241010T000000, start_date=20241011T014022, end_date=20241011T014024
[2024-10-11T01:40:24.962+0000] {standard_task_runner.py:110} ERROR - Failed to execute job 114 for task is_api_active (HTTPSConnectionPool(host='gorest.co.in', port=443): Max retries exceeded with url: /public/v2/posts/ (Caused by NameResolutionError("<urllib3.connection.HTTPSConnection object at 0x7fc7a8d318b0>: Failed to resolve 'gorest.co.in' ([Errno -2] Name or service not known)")); 7725)
[2024-10-11T01:40:25.028+0000] {local_task_job_runner.py:243} INFO - Task exited with return code 1
[2024-10-11T01:40:25.077+0000] {logging_mixin.py:188} WARNING - /home/***/.local/lib/python3.12/site-packages/***/models/baseoperator.py:1297 AirflowProviderDeprecationWarning: Call to deprecated class SimpleHttpOperator. (Class `SimpleHttpOperator` is deprecated and will be removed in a future release. Please use `HttpOperator` instead.)
[2024-10-11T01:40:25.196+0000] {taskinstance.py:3503} INFO - 0 downstream tasks scheduled from follow-on schedule check
[2024-10-11T01:40:25.227+0000] {local_task_job_runner.py:222} INFO - ::endgroup::
